Workbook

Sheet Case Study
A6: Case Study: Inventory Management (Managing Multiple Items)
A8: EcoDrive is an Automotive Manufacturing company which manufactures Spare Parts for both OEMs as well as After Market
A9: They have a manufacturing unit in Manesar
A10: They have distribution across Pan India for which they have multiple depots
A11: One of their Key depot is located in Pune
A13: Pune Depot manages and sells 240 SKUs
A14: They have categorized these 240 SKUs basis ABC method of Segmentation
A15: The Sales Data for last 1 year has been analyzed in details to determine the ABC Segment of each SKU
A17: Their Supply Chain department also has a well defined Inventory Policy for each of these Segments
A18: They also follow the Economic Order Quantity (EOQ) Concept for replenishing their stocks from the Plant
A19: Since, the Pune depot manages 240 SKUs, they need to consolidate their orders to the Plant for better co-ordination
A21: Average Lead time from Manesar to Pune is 5.44 days with Standard deviation of 1.06 days
A23: They also have standardized following costs
A25: Ordering Cost | B25: INR 250 per Order
A26: Inventory Holding Cost | B26: 20% p.a.
A27: Product Cost | B27: INR 150 per Unit
A28: Logistics Cost | B28: INR 8 per Unit
A30: As a Supply Chain Head, you want to assess the following
A31: a. Design the Inventory Policy for each Segment
A32: b. How to effectively manage multiple items at Pune depot
A33: c. Determine the most optimal way for replenishing orders from the plant

Sheet Policy
B2: Mean (LT) | C2: 5.4405348
B3: SD (LT) | C3: 1.0582424
B5: SKU Type | C5: Inv Policy | D5: Policy Type | E5: LoS (CSL) | F5: k | G5: G(k) | H5: LT | I5: R | J5: LT+R | K5: IFR
B6: A | C6: Continous | D6: (s,Q) | E6: 0.95 | F6: =_xlfn.NORM.S.INV(E6) -> 1.6448536 | G6: =_xlfn.NORM.DIST(F6,0,1,0)-F6*(1-_xlfn.NORM.DIST(F6,0,1,1)) -> 0.020892959 | H6: =+$C$2 -> 5.4405348 | I6: 0 | J6: =H6+I6 -> 5.4405348 | K6: =AVERAGE(Solution!$AA$6:$AA$38) -> 0.98695064
B7: B | C7: Continous | D7: (s,Q) | E7: 0.9 | F7: =_xlfn.NORM.S.INV(E7) -> 1.2815516 | G7: =_xlfn.NORM.DIST(F7,0,1,0)-F7*(1-_xlfn.NORM.DIST(F7,0,1,1)) -> 0.047343175 | H7: =+$C$2 -> 5.4405348 | I7: 0 | J7: =H7+I7 -> 5.4405348 | K7: =AVERAGE(Solution!$AA$39:$AA$129) -> 0.98124683
B8: C | C8: Periodic | D8: (R,S) | E8: 0.8 | F8: =_xlfn.NORM.S.INV(E8) -> 0.84162123 | G8: =_xlfn.NORM.DIST(F8,0,1,0)-F8*(1-_xlfn.NORM.DIST(F8,0,1,1)) -> 0.11163767 | H8: =+$C$2 -> 5.4405348 | I8: 30 | J8: =H8+I8 -> 35.440535 | K8: =AVERAGE(Solution!$AA$130:$AA$245) -> 0.90400998
B10: Ct | C10: 250 | E10: h | F10: 0.2
B12: Breakpoint
B13: w1 | C13: 1 | D13: weeks | E13: =(52*52*2)*$C$10/($F$10*C13*C14)/10^5 -> 33.8
B14: w2 | C14: 2 | D14: weeks | E14: =(52*52*2)*$C$10/($F$10*C14*C15)/10^5 -> 11.266667
B15: w3 | C15: 3 | D15: weeks | E15: =(52*52*2)*$C$10/($F$10*C15*C16)/10^5 -> 5.6333333
B16: w4 | C16: 4 | D16: weeks | E16: =(52*52*2)*$C$10/($F$10*C16*C17)/10^5 -> 3.38
B17: w5 | C17: 5 | D17: weeks | E17: =(52*52*2)*$C$10/($F$10*C17*C18)/10^5 -> 2.2533333
B18: w6 | C18: 6 | D18: weeks | E18: =(52*52*2)*$C$10/($F$10*C18*C19)/10^5 -> 1.6095238
B19: w7 | C19: 7 | D19: weeks | E19: =(52*52*2)*$C$10/($F$10*C19*C20)/10^5 -> 1.2071429
B20: w8 | C20: 8 | D20: weeks | E20: =(52*52*2)*$C$10/($F$10*C20*C21)/10^5 -> 0.93888889
B21: w9 | C21: 9 | D21: weeks | E21: =(52*52*2)*$C$10/($F$10*C21*C22)/10^5 -> 0.75111111
B22: w10 | C22: 10 | D22: weeks

Sheet Data
A1: Sales
A2: ProductCode | B2: Segment | C2: 43556 | D2: 43586 | E2: 43617 | F2: 43647 | G2: 43678 | H2: 43709 | I2: 43739 | J2: 43770 | K2: 43800 | L2: 43831 | M2: 43862 | N2: 43891
A3: SPD00486 | B3: A | C3: 2209.08 | D3: 1791.44 | E3: 6814.77 | F3: 7613.62 | G3: 3588.19 | H3: 6450.61 | I3: 2245.48 | J3: 2981.71 | K3: 4542.13 | L3: 3464.2 | M3: 3117.78 | N3: 3810.62
A4: SPD00545 | B4: A | C4: 1112.67 | D4: 1919.88 | E4: 3929.51 | F4: 3278.98 | G4: 1075.58 | H4: 1887.73 | I4: 421.01 | J4: 2217.37 | K4: 2729.03 | L4: 2591.02 | M4: 2331.918 | N4: 2850.122
A5: SPD00443 | B5: A | C5: 512.53 | D5: 1140.21 | E5: 2634.3 | F5: 3558.18 | G5: 960.91 | H5: 2880.78 | I5: 1460.83 | J5: 2507.72 | K5: 2849.28 | L5: 1546.54 | M5: 1391.886 | N5: 1701.194
A6: SPD00438 | B6: A | C6: 607.47 | D6: 1212.45 | E6: 1247.07 | F6: 2999.88 | G6: 607.62 | H6: 5840.42 | I6: 303.48 | J6: 2694.75 | K6: 3000.64 | L6: 1392.98 | M6: 1253.682 | N6: 1532.278
A7: SPD00385 | B7: A | C7: 560.99 | D7: 1123.91 | E7: 925.17 | F7: 2080.27 | G7: 1617.43 | H7: 3073.42 | I7: 164.58 | J7: 3170.78 | K7: 2542.1 | L7: 4055.79 | M7: 3650.211 | N7: 4461.369
A8: SPD00351 | B8: A | C8: 632.17 | D8: 1046.06 | E8: 3484.49 | F8: 3732.53 | G8: 411.36 | H8: 2701.68 | I8: 1077.04 | J8: 1805.23 | K8: 2951.48 | L8: 1432.33 | M8: 1488 | N8: 1894
A9: SPD00463 | B9: A | C9: 411.04 | D9: 724.62 | E9: 1729.99 | F9: 2236.49 | G9: 1903.84 | H9: 2771.61 | I9: 946.21 | J9: 2052.24 | K9: 3979.03 | L9: 2063.12 | M9: 1856.808 | N9: 2269.432
A10: SPD00430 | B10: A | C10: 209.84 | D10: 384.51 | E10: 2224.41 | F10: 1913.14 | G10: 2995.95 | H10: 2106.33 | I10: 105.12 | J10: 4251.44 | K10: 2620.57 | L10: 418.83 | M10: 376.947 | N10: 460.713
A11: SPD00309 | B11: A | C11: 568.69 | D11: 469.25 | E11: 1908.38 | F11: 2745.46 | G11: 616.08 | H11: 2503.1 | I11: 719.69 | J11: 1993.06 | K11: 2972.43 | L11: 1412.39 | M11: 1271.151 | N11: 1553.629
A12: SPD00900 | B12: A | C12: 0 | D12: 0 | E12: 1461.37 | F12: 1573.79 | G12: 1931.99 | H12: 691.69 | I12: 5770.22 | J12: 2935.67 | K12: 609.08 | L12: 747.42 | M12: 672.678 | N12: 822.162
A13: SPD00534 | B13: A | C13: 876.07 | D13: 505.19 | E13: 2959.8 | F13: 2941.82 | G13: 1080.87 | H13: 1964.77 | I13: 1324.01 | J13: 611.22 | K13: 2266.23 | L13: 1181.04 | M13: 1062.936 | N13: 1299.144
... A242: SPD00917 | B242: C | C242: 0 | D242: 0 | E242: 0 | F242: 0 | G242: 0 | H242: 0 | I242: 0 | J242: 10.82 | K242: 0 | L242: 0 | M242: 0 | N242: 0
A243: Grand Total | C243: 21044.68 | D243: 32814.12 | E243: 67769.14 | F243: 82235.31 | G243: 49759.42 | H243: 83058.54 | I243: 36023.47 | J243: 66462 | K243: 81723.68 | L243: 58603.16 | M243: =SUM(M3:M242) -> 52941.747 | N243: =SUM(N3:N242) -> 64781.913

Sheet Pivot
A3: Row Labels | B3: # SKUs | C3: Demand | D3: Sum of D
A4: A | B4: 33 | C4: 476586.53 | D4: 0.68355534
A5: B | B5: 91 | C5: 183993.7 | D5: 0.26389726
A6: C | B6: 116 | C6: 36636.95 | D6: 0.0525474
A7: Grand Total | B7: 240 | C7: 697217.18 | D7: 1
A10: Power of 2
A11: Re-Order | B11: # SKUs | C11: Demand | D11: Sum of D
A12: 8 | B12: 12 | C12: 283362.4 | D12: 0.40641913
A13: 16 | B13: 28 | C13: 229561.58 | D13: 0.32925405
A14: 32 | B14: 178 | C14: 166168.55 | D14: 0.23833112
A15: 64 | B15: 22 | C15: 18124.65 | D15: 0.025995702
A16: Grand Total | B16: 240 | C16: 697217.18 | D16: 1
A20: Breakpoints
A21: Re-Order | B21: # SKUs | C21: Demand | D21: Sum of D
A22: 1 | B22: 7 | C22: 193838.35 | D22: 0.27801717
A23: 2 | B23: 19 | C23: 235197.52 | D23: 0.33733753
A24: 3 | B24: 17 | C24: 95499.19 | D24: 0.13697194
A25: 4 | B25: 19 | C25: 54691.98 | D25: 0.078443248
A26: 5 | B26: 22 | C26: 40026.48 | D26: 0.057408912
A27: 6 | B27: 18 | C27: 23513.63 | D27: 0.033724972
A28: 7 | B28: 17 | C28: 15221.14 | D28: 0.021831275
A29: 8 | B29: 121 | C29: 39228.89 | D29: 0.05626495
A30: Grand Total | B30: 240 | C30: 697217.18 | D30: 1

Sheet Solution
P1: Mean (LT) | Q1: =+Policy!$C$2 -> 5.4405348 | S1: Ct | T1: 250 | X1: # Days/(Apr-Mar) | Y1: =AB1-AA1 -> 365 | AA1: 43556 | AB1: 43921
P2: SD (LT) | Q2: =Policy!$C$3 -> 1.0582424 | S2: h | T2: 0.2 | X2: #Days/Month | Y2: =(365/12) -> 30.416667
S3: C(Product) | T3: 150
A4: Sales | S4: C(logistics) | T4: 8
A5: ProductCode | B5: Segment | C5: 43556 | D5: 43586 | E5: 43617 | F5: 43647 | G5: 43678 | H5: 43709 | I5: 43739 | J5: 43770 | K5: 43800 | L5: 43831 | M5: 43862 | N5: 43891 | O5: D | P5: Mean(D) | Q5: SD(D) | R5: Deg_Vol | S5: EOQ | T5: Q | U5: LT | V5: Mean (Demand over LT) | W5: SD (Demand over LT) | X5: k | Y5: G(k) | Z5: E(US) | AA5: IFR | AB5: Re-Order Point | AC5: Order Upto (S) | AD5: Safety Stock | AE5: Cycle Stock | AF5: T* (Days) | AG5: T(Act) (Days) | AH5: DiCi | AI5: Re-order (Weeks)
A6: SPD00486 | B6: A | C6: 2209.08 | D6: 1791.44 | E6: 6814.77 | F6: 7613.62 | G6: 3588.19 | H6: 6450.61 | I6: 2245.48 | J6: 2981.71 | K6: 4542.13 | L6: 3464.2 | M6: 3117.78 | N6: 3810.62 | O6: =SUM(C6:N6) -> 48629.63 | P6: =AVERAGE(C6:N6) -> 4052.4692 | Q6: =STDEV(C6:N6) -> 1923.9819 | R6: =Q6/P6 -> 0.47476781 | S6: =SQRT(2*$T$1*O6*(365/$Y$1)/(($T$3+$T$4)*$T$2)) -> 877.18651 | U6: =VLOOKUP(B6,Policy!$B$5:$J$8,9,FALSE) -> 5.4405348 | V6: =(O6/$Y$1)*U6 -> 724.85259 | W6: =SQRT($Q$1*(Q6/SQRT($Y$2))^2+(O6/$Y$1)^2*($Q$2)^2) -> 825.82769 | X6: =VLOOKUP(B6,Policy!$B$5:$F$8,5,FALSE) -> 1.6448536 | Y6: =_xlfn.NORM.DIST(X6,0,1,0)-X6*(1-_xlfn.NORM.DIST(X6,0,1,1)) -> 0.020892959 | Z6: =W6*Y6 -> 17.253984 | AA6: =1-Z6/S6 -> 0.98033031 | AB6: =V6+X6*W6 -> 2083.2183 | AD6: =+X6*W6 -> 1358.3657 | AE6: =IF(B6="C",(T6/2),(S6/2)) -> 438.59325 | AF6: =S6/(O6/$Y$1) -> 6.5839093 | AG6: =2^ROUNDUP((LN(AF6/SQRT(2))/LN(2)),0) -> 8 | AH6: =O6*$T$3/10^5 -> 72.944445 | AI6: =IF(AH6>=Policy!$E$13,Policy!$C$13,IF(Solution!AH6>=Policy!$E$14,Policy!$C$14,IF(Solution!AH6>=Policy!$E$15,Policy!$C$15,IF(Solution!AH6>=Policy!$E$16,Policy!$C$16,IF(Solution!AH6>=Policy!$E$17,Policy!$C$17,IF(Solution!AH6>=Policy!$E$18,Policy!$C$18)))))) -> 1
A7: SPD00545 | B7: A | C7: 1112.67 | D7: 1919.88 | E7: 3929.51 | F7: 3278.98 | G7: 1075.58 | H7: 1887.73 | I7: 421.01 | J7: 2217.37 | K7: 2729.03 | L7: 2591.02 | M7: 2331.918 | N7: 2850.122 | O7: =SUM(C7:N7) -> 26344.82 | P7: =AVERAGE(C7:N7) -> 2195.4017 | Q7: =STDEV(C7:N7) -> 991.58611 | R7: =Q7/P7 -> 0.45166501 | S7: =SQRT(2*$T$1*O7*(365/$Y$1)/(($T$3+$T$4)*$T$2)) -> 645.63799 | U7: =VLOOKUP(B7,Policy!$B$5:$J$8,9,FALSE) -> 5.4405348 | V7: =(O7/$Y$1)*U7 -> 392.68469 | W7: =SQRT($Q$1*(Q7/SQRT($Y$2))^2+(O7/$Y$1)^2*($Q$2)^2) -> 426.26722 | X7: =VLOOKUP(B7,Policy!$B$5:$F$8,5,FALSE) -> 1.6448536 | Y7: =_xlfn.NORM.DIST(X7,0,1,0)-X7*(1-_xlfn.NORM.DIST(X7,0,1,1)) -> 0.020892959 | Z7: =W7*Y7 -> 8.9059836 | AA7: =1-Z7/S7 -> 0.98620592 | AB7: =V7+X7*W7 -> 1093.8319 | AD7: =+X7*W7 -> 701.14718 | AE7: =IF(B7="C",(T7/2),(S7/2)) -> 322.819 | AF7: =S7/(O7/$Y$1) -> 8.945131 | AG7: =2^ROUNDUP((LN(AF7/SQRT(2))/LN(2)),0) -> 8 | AH7: =O7*$T$3/10^5 -> 39.51723 | AI7: =IF(AH7>=Policy!$E$13,Policy!$C$13,IF(Solution!AH7>=Policy!$E$14,Policy!$C$14,IF(Solution!AH7>=Policy!$E$15,Policy!$C$15,IF(Solution!AH7>=Policy!$E$16,Policy!$C$16,IF(Solution!AH7>=Policy!$E$17,Policy!$C$17,IF(Solution!AH7>=Policy!$E$18,Policy!$C$18)))))) -> 1
A8: SPD00443 | B8: A | C8: 512.53 | D8: 1140.21 | E8: 2634.3 | F8: 3558.18 | G8: 960.91 | H8: 2880.78 | I8: 1460.83 | J8: 2507.72 | K8: 2849.28 | L8: 1546.54 | M8: 1391.886 | N8: 1701.194 | O8: =SUM(C8:N8) -> 23144.36 | P8: =AVERAGE(C8:N8) -> 1928.6967 | Q8: =STDEV(C8:N8) -> 929.85887 | R8: =Q8/P8 -> 0.48211774 | S8: =SQRT(2*$T$1*O8*(365/$Y$1)/(($T$3+$T$4)*$T$2)) -> 605.15141 | U8: =VLOOKUP(B8,Policy!$B$5:$J$8,9,FALSE) -> 5.4405348 | V8: =(O8/$Y$1)*U8 -> 344.97999 | W8: =SQRT($Q$1*(Q8/SQRT($Y$2))^2+(O8/$Y$1)^2*($Q$2)^2) -> 398.9458 | X8: =VLOOKUP(B8,Policy!$B$5:$F$8,5,FALSE) -> 1.6448536 | Y8: =_xlfn.NORM.DIST(X8,0,1,0)-X8*(1-_xlfn.NORM.DIST(X8,0,1,1)) -> 0.020892959 | Z8: =W8*Y8 -> 8.3351583 | AA8: =1-Z8/S8 -> 0.98622633 | AB8: =V8+X8*W8 -> 1001.1874 | AD8: =+X8*W8 -> 656.20745 | AE8: =IF(B8="C",(T8/2),(S8/2)) -> 302.5757 | AF8: =S8/(O8/$Y$1) -> 9.5435892 | AG8: =2^ROUNDUP((LN(AF8/SQRT(2))/LN(2)),0) -> 8 | AH8: =O8*$T$3/10^5 -> 34.71654 | AI8: =IF(AH8>=Policy!$E$13,Policy!$C$13,IF(Solution!AH8>=Policy!$E$14,Policy!$C$14,IF(Solution!AH8>=Policy!$E$15,Policy!$C$15,IF(Solution!AH8>=Policy!$E$16,Policy!$C$16,IF(Solution!AH8>=Policy!$E$17,Policy!$C$17,IF(Solution!AH8>=Policy!$E$18,Policy!$C$18)))))) -> 1
A9: SPD00438 | B9: A | C9: 607.47 | D9: 1212.45 | E9: 1247.07 | F9: 2999.88 | G9: 607.62 | H9: 5840.42 | I9: 303.48 | J9: 2694.75 | K9: 3000.64 | L9: 1392.98 | M9: 1253.682 | N9: 1532.278 | O9: =SUM(C9:N9) -> 22692.72 | P9: =AVERAGE(C9:N9) -> 1891.06 | Q9: =STDEV(C9:N9) -> 1542.6523 | R9: =Q9/P9 -> 0.81576063 | S9: =SQRT(2*$T$1*O9*(365/$Y$1)/(($T$3+$T$4)*$T$2)) -> 599.21784 | U9: =VLOOKUP(B9,Policy!$B$5:$J$8,9,FALSE) -> 5.4405348 | V9: =(O9/$Y$1)*U9 -> 338.24804 | W9: =SQRT($Q$1*(Q9/SQRT($Y$2))^2+(O9/$Y$1)^2*($Q$2)^2) -> 655.73765 | X9: =VLOOKUP(B9,Policy!$B$5:$F$8,5,FALSE) -> 1.6448536 | Y9: =_xlfn.NORM.DIST(X9,0,1,0)-X9*(1-_xlfn.NORM.DIST(X9,0,1,1)) -> 0.020892959 | Z9: =W9*Y9 -> 13.7003 | AA9: =1-Z9/S9 -> 0.97713636 | AB9: =V9+X9*W9 -> 1416.8405 | AD9: =+X9*W9 -> 1078.5925 | AE9: =IF(B9="C",(T9/2),(S9/2)) -> 299.60892 | AF9: =S9/(O9/$Y$1) -> 9.6380916 | AG9: =2^ROUNDUP((LN(AF9/SQRT(2))/LN(2)),0) -> 8 | AH9: =O9*$T$3/10^5 -> 34.03908 | AI9: =IF(AH9>=Policy!$E$13,Policy!$C$13,IF(Solution!AH9>=Policy!$E$14,Policy!$C$14,IF(Solution!AH9>=Policy!$E$15,Policy!$C$15,IF(Solution!AH9>=Policy!$E$16,Policy!$C$16,IF(Solution!AH9>=Policy!$E$17,Policy!$C$17,IF(Solution!AH9>=Policy!$E$18,Policy!$C$18)))))) -> 1
A10: SPD00385 | B10: A | C10: 560.99 | D10: 1123.91 | E10: 925.17 | F10: 2080.27 | G10: 1617.43 | H10: 3073.42 | I10: 164.58 | J10: 3170.78 | K10: 2542.1 | L10: 4055.79 | M10: 3650.211 | N10: 4461.369 | O10: =SUM(C10:N10) -> 27426.02 | P10: =AVERAGE(C10:N10) -> 2285.5017 | Q10: =STDEV(C10:N10) -> 1425.7889 | R10: =Q10/P10 -> 0.62384066 | S10: =SQRT(2*$T$1*O10*(365/$Y$1)/(($T$3+$T$4)*$T$2)) -> 658.75338 | U10: =VLOOKUP(B10,Policy!$B$5:$J$8,9,FALSE) -> 5.4405348 | V10: =(O10/$Y$1)*U10 -> 408.8006 | W10: =SQRT($Q$1*(Q10/SQRT($Y$2))^2+(O10/$Y$1)^2*($Q$2)^2) -> 608.22419 | X10: =VLOOKUP(B10,Policy!$B$5:$F$8,5,FALSE) -> 1.6448536 | Y10: =_xlfn.NORM.DIST(X10,0,1,0)-X10*(1-_xlfn.NORM.DIST(X10,0,1,1)) -> 0.020892959 | Z10: =W10*Y10 -> 12.707603 | AA10: =1-Z10/S10 -> 0.98070962 | AB10: =V10+X10*W10 -> 1409.2404 | AD10: =+X10*W10 -> 1000.4398 | AE10: =IF(B10="C",(T10/2),(S10/2)) -> 329.37669 | AF10: =S10/(O10/$Y$1) -> 8.7670389 | AG10: =2^ROUNDUP((LN(AF10/SQRT(2))/LN(2)),0) -> 8 | AH10: =O10*$T$3/10^5 -> 41.13903 | AI10: =IF(AH10>=Policy!$E$13,Policy!$C$13,IF(Solution!AH10>=Policy!$E$14,Policy!$C$14,IF(Solution!AH10>=Policy!$E$15,Policy!$C$15,IF(Solution!AH10>=Policy!$E$16,Policy!$C$16,IF(Solution!AH10>=Policy!$E$17,Policy!$C$17,IF(Solution!AH10>=Policy!$E$18,Policy!$C$18)))))) -> 1
A11: SPD00351 | B11: A | C11: 632.17 | D11: 1046.06 | E11: 3484.49 | F11: 3732.53 | G11: 411.36 | H11: 2701.68 | I11: 1077.04 | J11: 1805.23 | K11: 2951.48 | L11: 1432.33 | M11: 1488 | N11: 1894 | O11: =SUM(C11:N11) -> 22656.37 | P11: =AVERAGE(C11:N11) -> 1888.0308 | Q11: =STDEV(C11:N11) -> 1097.2176 | R11: =Q11/P11 -> 0.58114392 | S11: =SQRT(2*$T$1*O11*(365/$Y$1)/(($T$3+$T$4)*$T$2)) -> 598.73773 | U11: =VLOOKUP(B11,Policy!$B$5:$J$8,9,FALSE) -> 5.4405348 | V11: =(O11/$Y$1)*U11 -> 337.70622 | W11: =SQRT($Q$1*(Q11/SQRT($Y$2))^2+(O11/$Y$1)^2*($Q$2)^2) -> 468.66864 | X11: =VLOOKUP(B11,Policy!$B$5:$F$8,5,FALSE) -> 1.6448536 | Y11: =_xlfn.NORM.DIST(X11,0,1,0)-X11*(1-_xlfn.NORM.DIST(X11,0,1,1)) -> 0.020892959 | Z11: =W11*Y11 -> 9.7918747 | AA11: =1-Z11/S11 -> 0.9836458 | AB11: =V11+X11*W11 -> 1108.5975 | AD11: =+X11*W11 -> 770.89132 | AE11: =IF(B11="C",(T11/2),(S11/2)) -> 299.36886 | AF11: =S11/(O11/$Y$1) -> 9.6458202 | AG11: =2^ROUNDUP((LN(AF11/SQRT(2))/LN(2)),0) -> 8 | AH11: =O11*$T$3/10^5 -> 33.984555 | AI11: =IF(AH11>=Policy!$E$13,Policy!$C$13,IF(Solution!AH11>=Policy!$E$14,Policy!$C$14,IF(Solution!AH11>=Policy!$E$15,Policy!$C$15,IF(Solution!AH11>=Policy!$E$16,Policy!$C$16,IF(Solution!AH11>=Policy!$E$17,Policy!$C$17,IF(Solution!AH11>=Policy!$E$18,Policy!$C$18)))))) -> 1
A12: SPD00463 | B12: A | C12: 411.04 | D12: 724.62 | E12: 1729.99 | F12: 2236.49 | G12: 1903.84 | H12: 2771.61 | I12: 946.21 | J12: 2052.24 | K12: 3979.03 | L12: 2063.12 | M12: 1856.808 | N12: 2269.432 | O12: =SUM(C12:N12) -> 22944.43 | P12: =AVERAGE(C12:N12) -> 1912.0358 | Q12: =STDEV(C12:N12) -> 949.58561 | R12: =Q12/P12 -> 0.49663589 | S12: =SQRT(2*$T$1*O12*(365/$Y$1)/(($T$3+$T$4)*$T$2)) -> 602.53197 | U12: =VLOOKUP(B12,Policy!$B$5:$J$8,9,FALSE) -> 5.4405348 | V12: =(O12/$Y$1)*U12 -> 341.99992 | W12: =SQRT($Q$1*(Q12/SQRT($Y$2))^2+(O12/$Y$1)^2*($Q$2)^2) -> 407.07719 | X12: =VLOOKUP(B12,Policy!$B$5:$F$8,5,FALSE) -> 1.6448536 | Y12: =_xlfn.NORM.DIST(X12,0,1,0)-X12*(1-_xlfn.NORM.DIST(X12,0,1,1)) -> 0.020892959 | Z12: =W12*Y12 -> 8.5050471 | AA12: =1-Z12/S12 -> 0.98588449 | AB12: =V12+X12*W12 -> 1011.5823 | AD12: =+X12*W12 -> 669.5824 | AE12: =IF(B12="C",(T12/2),(S12/2)) -> 301.26599 | AF12: =S12/(O12/$Y$1) -> 9.5850788 | AG12: =2^ROUNDUP((LN(AF12/SQRT(2))/LN(2)),0) -> 8 | AH12: =O12*$T$3/10^5 -> 34.416645 | AI12: =IF(AH12>=Policy!$E$13,Policy!$C$13,IF(Solution!AH12>=Policy!$E$14,Policy!$C$14,IF(Solution!AH12>=Policy!$E$15,Policy!$C$15,IF(Solution!AH12>=Policy!$E$16,Policy!$C$16,IF(Solution!AH12>=Policy!$E$17,Policy!$C$17,IF(Solution!AH12>=Policy!$E$18,Policy!$C$18)))))) -> 1
A13: SPD00430 | B13: A | C13: 209.84 | D13: 384.51 | E13: 2224.41 | F13: 1913.14 | G13: 2995.95 | H13: 2106.33 | I13: 105.12 | J13: 4251.44 | K13: 2620.57 | L13: 418.83 | M13: 376.947 | N13: 460.713 | O13: =SUM(C13:N13) -> 18067.8 | P13: =AVERAGE(C13:N13) -> 1505.65 | Q13: =STDEV(C13:N13) -> 1364.8672 | R13: =Q13/P13 -> 0.90649702 | S13: =SQRT(2*$T$1*O13*(365/$Y$1)/(($T$3+$T$4)*$T$2)) -> 534.6802 | U13: =VLOOKUP(B13,Policy!$B$5:$J$8,9,FALSE) -> 5.4405348 | V13: =(O13/$Y$1)*U13 -> 269.31095 | W13: =SQRT($Q$1*(Q13/SQRT($Y$2))^2+(O13/$Y$1)^2*($Q$2)^2) -> 579.61066 | X13: =VLOOKUP(B13,Policy!$B$5:$F$8,5,FALSE) -> 1.6448536 | Y13: =_xlfn.NORM.DIST(X13,0,1,0)-X13*(1-_xlfn.NORM.DIST(X13,0,1,1)) -> 0.020892959 | Z13: =W13*Y13 -> 12.109782 | AA13: =1-Z13/S13 -> 0.97735136 | AB13: =V13+X13*W13 -> 1222.6856 | AD13: =+X13*W13 -> 953.3747 | AE13: =IF(B13="C",(T13/2),(S13/2)) -> 267.3401 | AF13: =S13/(O13/$Y$1) -> 10.801441 | AG13: =2^ROUNDUP((LN(AF13/SQRT(2))/LN(2)),0) -> 8 | AH13: =O13*$T$3/10^5 -> 27.1017 | AI13: =IF(AH13>=Policy!$E$13,Policy!$C$13,IF(Solution!AH13>=Policy!$E$14,Policy!$C$14,IF(Solution!AH13>=Policy!$E$15,Policy!$C$15,IF(Solution!AH13>=Policy!$E$16,Policy!$C$16,IF(Solution!AH13>=Policy!$E$17,Policy!$C$17,IF(Solution!AH13>=Policy!$E$18,Policy!$C$18)))))) -> 2
A14: SPD00309 | B14: A | C14: 568.69 | D14: 469.25 | E14: 1908.38 | F14: 2745.46 | G14: 616.08 | H14: 2503.1 | I14: 719.69 | J14: 1993.06 | K14: 2972.43 | L14: 1412.39 | M14: 1271.151 | N14: 1553.629 | O14: =SUM(C14:N14) -> 18733.31 | P14: =AVERAGE(C14:N14) -> 1561.1092 | Q14: =STDEV(C14:N14) -> 877.67287 | R14: =Q14/P14 -> 0.56221108 | S14: =SQRT(2*$T$1*O14*(365/$Y$1)/(($T$3+$T$4)*$T$2)) -> 544.43836 | U14: =VLOOKUP(B14,Policy!$B$5:$J$8,9,FALSE) -> 5.4405348 | V14: =(O14/$Y$1)*U14 -> 279.23076 | W14: =SQRT($Q$1*(Q14/SQRT($Y$2))^2+(O14/$Y$1)^2*($Q$2)^2) -> 375.14376 | X14: =VLOOKUP(B14,Policy!$B$5:$F$8,5,FALSE) -> 1.6448536 | Y14: =_xlfn.NORM.DIST(X14,0,1,0)-X14*(1-_xlfn.NORM.DIST(X14,0,1,1)) -> 0.020892959 | Z14: =W14*Y14 -> 7.8378633 | AA14: =1-Z14/S14 -> 0.98560376 | AB14: =V14+X14*W14 -> 896.28734 | AD14: =+X14*W14 -> 617.05658 | AE14: =IF(B14="C",(T14/2),(S14/2)) -> 272.21918 | AF14: =S14/(O14/$Y$1) -> 10.607843 | AG14: =2^ROUNDUP((LN(AF14/SQRT(2))/LN(2)),0) -> 8 | AH14: =O14*$T$3/10^5 -> 28.099965 | AI14: =IF(AH14>=Policy!$E$13,Policy!$C$13,IF(Solution!AH14>=Policy!$E$14,Policy!$C$14,IF(Solution!AH14>=Policy!$E$15,Policy!$C$15,IF(Solution!AH14>=Policy!$E$16,Policy!$C$16,IF(Solution!AH14>=Policy!$E$17,Policy!$C$17,IF(Solution!AH14>=Policy!$E$18,Policy!$C$18)))))) -> 2
A15: SPD00900 | B15: A | C15: 0 | D15: 0 | E15: 1461.37 | F15: 1573.79 | G15: 1931.99 | H15: 691.69 | I15: 5770.22 | J15: 2935.67 | K15: 609.08 | L15: 747.42 | M15: 672.678 | N15: 822.162 | O15: =SUM(C15:N15) -> 17216.07 | P15: =AVERAGE(C15:N15) -> 1434.6725 | Q15: =STDEV(C15:N15) -> 1598.1715 | R15: =Q15/P15 -> 1.1139626 | S15: =SQRT(2*$T$1*O15*(365/$Y$1)/(($T$3+$T$4)*$T$2)) -> 521.92545 | U15: =VLOOKUP(B15,Policy!$B$5:$J$8,9,FALSE) -> 5.4405348 | V15: =(O15/$Y$1)*U15 -> 256.61542 | W15: =SQRT($Q$1*(Q15/SQRT($Y$2))^2+(O15/$Y$1)^2*($Q$2)^2) -> 677.74975 | X15: =VLOOKUP(B15,Policy!$B$5:$F$8,5,FALSE) -> 1.6448536 | Y15: =_xlfn.NORM.DIST(X15,0,1,0)-X15*(1-_xlfn.NORM.DIST(X15,0,1,1)) -> 0.020892959 | Z15: =W15*Y15 -> 14.160198 | AA15: =1-Z15/S15 -> 0.97286931 | AB15: =V15+X15*W15 -> 1371.4146 | AD15: =+X15*W15 -> 1114.7991 | AE15: =IF(B15="C",(T15/2),(S15/2)) -> 260.96272 | AF15: =S15/(O15/$Y$1) -> 11.065405 | AG15: =2^ROUNDUP((LN(AF15/SQRT(2))/LN(2)),0) -> 8 | AH15: =O15*$T$3/10^5 -> 25.824105 | AI15: =IF(AH15>=Policy!$E$13,Policy!$C$13,IF(Solution!AH15>=Policy!$E$14,Policy!$C$14,IF(Solution!AH15>=Policy!$E$15,Policy!$C$15,IF(Solution!AH15>=Policy!$E$16,Policy!$C$16,IF(Solution!AH15>=Policy!$E$17,Policy!$C$17,IF(Solution!AH15>=Policy!$E$18,Policy!$C$18)))))) -> 2
A16: SPD00534 | B16: A | C16: 876.07 | D16: 505.19 | E16: 2959.8 | F16: 2941.82 | G16: 1080.87 | H16: 1964.77 | I16: 1324.01 | J16: 611.22 | K16: 2266.23 | L16: 1181.04 | M16: 1062.936 | N16: 1299.144 | O16: =SUM(C16:N16) -> 18073.1 | P16: =AVERAGE(C16:N16) -> 1506.0917 | Q16: =STDEV(C16:N16) -> 837.80811 | R16: =Q16/P16 -> 0.55627963 | S16: =SQRT(2*$T$1*O16*(365/$Y$1)/(($T$3+$T$4)*$T$2)) -> 534.75861 | U16: =VLOOKUP(B16,Policy!$B$5:$J$8,9,FALSE) -> 5.4405348 | V16: =(O16/$Y$1)*U16 -> 269.38995 | W16: =SQRT($Q$1*(Q16/SQRT($Y$2))^2+(O16/$Y$1)^2*($Q$2)^2) -> 358.18482 | X16: =VLOOKUP(B16,Policy!$B$5:$F$8,5,FALSE) -> 1.6448536 | Y16: =_xlfn.NORM.DIST(X16,0,1,0)-X16*(1-_xlfn.NORM.DIST(X16,0,1,1)) -> 0.020892959 | Z16: =W16*Y16 -> 7.4835408 | AA16: =1-Z16/S16 -> 0.98600576 | AB16: =V16+X16*W16 -> 858.55155 | AD16: =+X16*W16 -> 589.1616 | AE16: =IF(B16="C",(T16/2),(S16/2)) -> 267.37931 | AF16: =S16/(O16/$Y$1) -> 10.799857 | AG16: =2^ROUNDUP((LN(AF16/SQRT(2))/LN(2)),0) -> 8 | AH16: =O16*$T$3/10^5 -> 27.10965 | AI16: =IF(AH16>=Policy!$E$13,Policy!$C$13,IF(Solution!AH16>=Policy!$E$14,Policy!$C$14,IF(Solution!AH16>=Policy!$E$15,Policy!$C$15,IF(Solution!AH16>=Policy!$E$16,Policy!$C$16,IF(Solution!AH16>=Policy!$E$17,Policy!$C$17,IF(Solution!AH16>=Policy!$E$18,Policy!$C$18)))))) -> 2
A17: SPD00354 | B17: A | C17: 532.88 | D17: 1120.35 | E17: 2096.88 | F17: 1795.1 | G17: 1065.99 | H17: 1882.05 | I17: 965.25 | J17: 1442.14 | K17: 1380.93 | L17: 1717.4 | M17: 1545.66 | N17: 1889.14 | O17: =SUM(C17:N17) -> 17433.77 | P17: =AVERAGE(C17:N17) -> 1452.8142 | Q17: =STDEV(C17:N17) -> 460.69852 | R17: =Q17/P17 -> 0.31710767 | S17: =SQRT(2*$T$1*O17*(365/$Y$1)/(($T$3+$T$4)*$T$2)) -> 525.215 | U17: =VLOOKUP(B17,Policy!$B$5:$J$8,9,FALSE) -> 5.4405348 | V17: =(O17/$Y$1)*U17 -> 259.86036 | W17: =SQRT($Q$1*(Q17/SQRT($Y$2))^2+(O17/$Y$1)^2*($Q$2)^2) -> 201.29116 | X17: =VLOOKUP(B17,Policy!$B$5:$F$8,5,FALSE) -> 1.6448536 | Y17: =_xlfn.NORM.DIST(X17,0,1,0)-X17*(1-_xlfn.NORM.DIST(X17,0,1,1)) -> 0.020892959 | Z17: =W17*Y17 -> 4.2055679 | AA17: =1-Z17/S17 -> 0.99199267 | AB17: =V17+X17*W17 -> 590.95485 | AD17: =+X17*W17 -> 331.09449 | AE17: =IF(B17="C",(T17/2),(S17/2)) -> 262.6075 | AF17: =S17/(O17/$Y$1) -> 10.9961 | AG17: =2^ROUNDUP((LN(AF17/SQRT(2))/LN(2)),0) -> 8 | AH17: =O17*$T$3/10^5 -> 26.150655 | AI17: =IF(AH17>=Policy!$E$13,Policy!$C$13,IF(Solution!AH17>=Policy!$E$14,Policy!$C$14,IF(Solution!AH17>=Policy!$E$15,Policy!$C$15,IF(Solution!AH17>=Policy!$E$16,Policy!$C$16,IF(Solution!AH17>=Policy!$E$17,Policy!$C$17,IF(Solution!AH17>=Policy!$E$18,Policy!$C$18)))))) -> 2
... A101: SPD00134 | B101: B | C101: 0 | D101: 0 | E101: 35.58 | F101: 189.47 | G101: 143.08 | H101: 107.16 | I101: 215.16 | J101: 142.4 | K101: 0 | L101: 177.53 | M101: 159.777 | N101: 195.283 | O101: =SUM(C101:N101) -> 1365.44 | P101: =AVERAGE(C101:N101) -> 113.78667 | Q101: =STDEV(C101:N101) -> 82.849112 | R101: =Q101/P101 -> 0.72810914 | S101: =SQRT(2*$T$1*O101*(365/$Y$1)/(($T$3+$T$4)*$T$2)) -> 146.98661 | U101: =VLOOKUP(B101,Policy!$B$5:$J$8,9,FALSE) -> 5.4405348 | V101: =(O101/$Y$1)*U101 -> 20.352668 | W101: =SQRT($Q$1*(Q101/SQRT($Y$2))^2+(O101/$Y$1)^2*($Q$2)^2) -> 35.262022 | X101: =VLOOKUP(B101,Policy!$B$5:$F$8,5,FALSE) -> 1.2815516 | Y101: =_xlfn.NORM.DIST(X101,0,1,0)-X101*(1-_xlfn.NORM.DIST(X101,0,1,1)) -> 0.047343175 | Z101: =W101*Y101 -> 1.6694161 | AA101: =1-Z101/S101 -> 0.98864239 | AB101: =V101+X101*W101 -> 65.542768 | AD101: =+X101*W101 -> 45.190099 | AE101: =IF(B101="C",(T101/2),(S101/2)) -> 73.493305 | AF101: =S101/(O101/$Y$1) -> 39.291446 | AG101: =2^ROUNDUP((LN(AF101/SQRT(2))/LN(2)),0) -> 32 | AH101: =O101*$T$3/10^5 -> 2.04816 | AI101: =IF(AH101>=Policy!$E$13,Policy!$C$13,IF(Solution!AH101>=Policy!$E$14,Policy!$C$14,IF(Solution!AH101>=Policy!$E$15,Policy!$C$15,IF(Solution!AH101>=Policy!$E$16,Policy!$C$16,IF(Solution!AH101>=Policy!$E$17,Policy!$C$17,IF(Solution!AH101>=Policy!$E$18,Policy!$C$18)))))) -> 6
A102: SPD00489 | B102: B | C102: 0 | D102: 0 | E102: 100.32 | F102: 265.94 | G102: 262.81 | H102: 54.93 | I102: 0 | J102: 131.85 | K102: 164.2 | L102: 0 | M102: 0 | N102: 0 | O102: =SUM(C102:N102) -> 980.05 | P102: =AVERAGE(C102:N102) -> 81.670833 | Q102: =STDEV(C102:N102) -> 103.21168 | R102: =Q102/P102 -> 1.263752 | S102: =SQRT(2*$T$1*O102*(365/$Y$1)/(($T$3+$T$4)*$T$2)) -> 124.52759 | U102: =VLOOKUP(B102,Policy!$B$5:$J$8,9,FALSE) -> 5.4405348 | V102: =(O102/$Y$1)*U102 -> 14.608209 | W102: =SQRT($Q$1*(Q102/SQRT($Y$2))^2+(O102/$Y$1)^2*($Q$2)^2) -> 43.743346 | X102: =VLOOKUP(B102,Policy!$B$5:$F$8,5,FALSE) -> 1.2815516 | Y102: =_xlfn.NORM.DIST(X102,0,1,0)-X102*(1-_xlfn.NORM.DIST(X102,0,1,1)) -> 0.047343175 | Z102: =W102*Y102 -> 2.0709489 | AA102: =1-Z102/S102 -> 0.98336956 | AB102: =V102+X102*W102 -> 70.667562 | AD102: =+X102*W102 -> 56.059353 | AE102: =IF(B102="C",(T102/2),(S102/2)) -> 62.263794 | AF102: =S102/(O102/$Y$1) -> 46.377807 | AG102: =2^ROUNDUP((LN(AF102/SQRT(2))/LN(2)),0) -> 64 | AH102: =O102*$T$3/10^5 -> 1.470075 | AI102: =IF(AH102>=Policy!$E$13,Policy!$C$13,IF(Solution!AH102>=Policy!$E$14,Policy!$C$14,IF(Solution!AH102>=Policy!$E$15,Policy!$C$15,IF(Solution!AH102>=Policy!$E$16,Policy!$C$16,IF(Solution!AH102>=Policy!$E$17,Policy!$C$17,IF(Solution!AH102>=Policy!$E$18,Policy!$C$18,IF(AH102>=Policy!$E$19,Policy!$C$19,Policy!$C$20))))))) -> 7
A103: SPD00688 | B103: B | C103: 0 | D103: 260.97 | E103: 0 | F103: 0 | G103: 296.21 | H103: 0 | I103: 0 | J103: 0 | K103: 186.28 | L103: 223.42 | M103: 201.078 | N103: 245.762 | O103: =SUM(C103:N103) -> 1413.72 | P103: =AVERAGE(C103:N103) -> 117.81 | Q103: =STDEV(C103:N103) -> 126.03874 | R103: =Q103/P103 -> 1.0698476 | S103: =SQRT(2*$T$1*O103*(365/$Y$1)/(($T$3+$T$4)*$T$2)) -> 149.56265 | U103: =VLOOKUP(B103,Policy!$B$5:$J$8,9,FALSE) -> 5.4405348 | V103: =(O103/$Y$1)*U103 -> 21.072309 | W103: =SQRT($Q$1*(Q103/SQRT($Y$2))^2+(O103/$Y$1)^2*($Q$2)^2) -> 53.462487 | X103: =VLOOKUP(B103,Policy!$B$5:$F$8,5,FALSE) -> 1.2815516 | Y103: =_xlfn.NORM.DIST(X103,0,1,0)-X103*(1-_xlfn.NORM.DIST(X103,0,1,1)) -> 0.047343175 | Z103: =W103*Y103 -> 2.5310839 | AA103: =1-Z103/S103 -> 0.98307677 | AB103: =V103+X103*W103 -> 89.587243 | AD103: =+X103*W103 -> 68.514934 | AE103: =IF(B103="C",(T103/2),(S103/2)) -> 74.781327 | AF103: =S103/(O103/$Y$1) -> 38.614696 | AG103: =2^ROUNDUP((LN(AF103/SQRT(2))/LN(2)),0) -> 32 | AH103: =O103*$T$3/10^5 -> 2.12058 | AI103: =IF(AH103>=Policy!$E$13,Policy!$C$13,IF(Solution!AH103>=Policy!$E$14,Policy!$C$14,IF(Solution!AH103>=Policy!$E$15,Policy!$C$15,IF(Solution!AH103>=Policy!$E$16,Policy!$C$16,IF(Solution!AH103>=Policy!$E$17,Policy!$C$17,IF(Solution!AH103>=Policy!$E$18,Policy!$C$18)))))) -> 6
A104: SPD00634 | B104: B | C104: 0 | D104: 148.74 | E104: 161.78 | F104: 53.85 | G104: 27.03 | H104: 175.57 | I104: 27.06 | J104: 217.24 | K104: 107.51 | L104: 0 | M104: 0 | N104: 0 | O104: =SUM(C104:N104) -> 918.78 | P104: =AVERAGE(C104:N104) -> 76.565 | Q104: =STDEV(C104:N104) -> 80.841649 | R104: =Q104/P104 -> 1.0558565 | S104: =SQRT(2*$T$1*O104*(365/$Y$1)/(($T$3+$T$4)*$T$2)) -> 120.57221 | U104: =VLOOKUP(B104,Policy!$B$5:$J$8,9,FALSE) -> 5.4405348 | V104: =(O104/$Y$1)*U104 -> 13.694944 | W104: =SQRT($Q$1*(Q104/SQRT($Y$2))^2+(O104/$Y$1)^2*($Q$2)^2) -> 34.293697 | X104: =VLOOKUP(B104,Policy!$B$5:$F$8,5,FALSE) -> 1.2815516 | Y104: =_xlfn.NORM.DIST(X104,0,1,0)-X104*(1-_xlfn.NORM.DIST(X104,0,1,1)) -> 0.047343175 | Z104: =W104*Y104 -> 1.6235725 | AA104: =1-Z104/S104 -> 0.98653444 | AB104: =V104+X104*W104 -> 57.644085 | AD104: =+X104*W104 -> 43.949141 | AE104: =IF(B104="C",(T104/2),(S104/2)) -> 60.286106 | AF104: =S104/(O104/$Y$1) -> 47.899233 | AG104: =2^ROUNDUP((LN(AF104/SQRT(2))/LN(2)),0) -> 64 | AH104: =O104*$T$3/10^5 -> 1.37817 | AI104: =IF(AH104>=Policy!$E$13,Policy!$C$13,IF(Solution!AH104>=Policy!$E$14,Policy!$C$14,IF(Solution!AH104>=Policy!$E$15,Policy!$C$15,IF(Solution!AH104>=Policy!$E$16,Policy!$C$16,IF(Solution!AH104>=Policy!$E$17,Policy!$C$17,IF(Solution!AH104>=Policy!$E$18,Policy!$C$18,IF(AH104>=Policy!$E$19,Policy!$C$19,Policy!$C$20))))))) -> 7
A105: SPD00999 | B105: B | C105: 0 | D105: 0 | E105: 0 | F105: 0 | G105: 66.6 | H105: 365.41 | I105: 332.84 | J105: 133.09 | K105: 0 | L105: 0 | M105: 0 | N105: 0 | O105: =SUM(C105:N105) -> 897.94 | P105: =AVERAGE(C105:N105) -> 74.828333 | Q105: =STDEV(C105:N105) -> 134.59167 | R105: =Q105/P105 -> 1.7986725 | S105: =SQRT(2*$T$1*O105*(365/$Y$1)/(($T$3+$T$4)*$T$2)) -> 119.19694 | U105: =VLOOKUP(B105,Policy!$B$5:$J$8,9,FALSE) -> 5.4405348 | V105: =(O105/$Y$1)*U105 -> 13.384312 | W105: =SQRT($Q$1*(Q105/SQRT($Y$2))^2+(O105/$Y$1)^2*($Q$2)^2) -> 56.981898 | X105: =VLOOKUP(B105,Policy!$B$5:$F$8,5,FALSE) -> 1.2815516 | Y105: =_xlfn.NORM.DIST(X105,0,1,0)-X105*(1-_xlfn.NORM.DIST(X105,0,1,1)) -> 0.047343175 | Z105: =W105*Y105 -> 2.697704 | AA105: =1-Z105/S105 -> 0.97736767 | AB105: =V105+X105*W105 -> 86.409552 | AD105: =+X105*W105 -> 73.025241 | AE105: =IF(B105="C",(T105/2),(S105/2)) -> 59.598472 | AF105: =S105/(O105/$Y$1) -> 48.451884 | AG105: =2^ROUNDUP((LN(AF105/SQRT(2))/LN(2)),0) -> 64 | AH105: =O105*$T$3/10^5 -> 1.34691 | AI105: =IF(AH105>=Policy!$E$13,Policy!$C$13,IF(Solution!AH105>=Policy!$E$14,Policy!$C$14,IF(Solution!AH105>=Policy!$E$15,Policy!$C$15,IF(Solution!AH105>=Policy!$E$16,Policy!$C$16,IF(Solution!AH105>=Policy!$E$17,Policy!$C$17,IF(Solution!AH105>=Policy!$E$18,Policy!$C$18,IF(AH105>=Policy!$E$19,Policy!$C$19,Policy!$C$20))))))) -> 7
A106: SPD00053 | B106: B | C106: 0 | D106: 64.75 | E106: 97.07 | F106: 194.61 | G106: 43.31 | H106: 162.58 | I106: 130.02 | J106: 129.79 | K106: 64.97 | L106: 0 | M106: 0 | N106: 0 | O106: =SUM(C106:N106) -> 887.1 | P106: =AVERAGE(C106:N106) -> 73.925 | Q106: =STDEV(C106:N106) -> 68.88006 | R106: =Q106/P106 -> 0.93175597 | S106: =SQRT(2*$T$1*O106*(365/$Y$1)/(($T$3+$T$4)*$T$2)) -> 118.47528 | U106: =VLOOKUP(B106,Policy!$B$5:$J$8,9,FALSE) -> 5.4405348 | V106: =(O106/$Y$1)*U106 -> 13.222735 | W106: =SQRT($Q$1*(Q106/SQRT($Y$2))^2+(O106/$Y$1)^2*($Q$2)^2) -> 29.244527 | X106: =VLOOKUP(B106,Policy!$B$5:$F$8,5,FALSE) -> 1.2815516 | Y106: =_xlfn.NORM.DIST(X106,0,1,0)-X106*(1-_xlfn.NORM.DIST(X106,0,1,1)) -> 0.047343175 | Z106: =W106*Y106 -> 1.3845287 | AA106: =1-Z106/S106 -> 0.98831378 | AB106: =V106+X106*W106 -> 50.701104 | AD106: =+X106*W106 -> 37.478369 | AE106: =IF(B106="C",(T106/2),(S106/2)) -> 59.237641 | AF106: =S106/(O106/$Y$1) -> 48.747016 | AG106: =2^ROUNDUP((LN(AF106/SQRT(2))/LN(2)),0) -> 64 | AH106: =O106*$T$3/10^5 -> 1.33065 | AI106: =IF(AH106>=Policy!$E$13,Policy!$C$13,IF(Solution!AH106>=Policy!$E$14,Policy!$C$14,IF(Solution!AH106>=Policy!$E$15,Policy!$C$15,IF(Solution!AH106>=Policy!$E$16,Policy!$C$16,IF(Solution!AH106>=Policy!$E$17,Policy!$C$17,IF(Solution!AH106>=Policy!$E$18,Policy!$C$18,IF(AH106>=Policy!$E$19,Policy!$C$19,Policy!$C$20))))))) -> 7
A107: SPD00042 | B107: B | C107: 0 | D107: 0 | E107: 34.52 | F107: 0 | G107: 173.74 | H107: 104.32 | I107: 139.11 | J107: 69.39 | K107: 173.74 | L107: 171.85 | M107: 154.665 | N107: 189.035 | O107: =SUM(C107:N107) -> 1210.37 | P107: =AVERAGE(C107:N107) -> 100.86417 | Q107: =STDEV(C107:N107) -> 76.108169 | R107: =Q107/P107 -> 0.75456102 | S107: =SQRT(2*$T$1*O107*(365/$Y$1)/(($T$3+$T$4)*$T$2)) -> 138.38867 | U107: =VLOOKUP(B107,Policy!$B$5:$J$8,9,FALSE) -> 5.4405348 | V107: =(O107/$Y$1)*U107 -> 18.041261 | W107: =SQRT($Q$1*(Q107/SQRT($Y$2))^2+(O107/$Y$1)^2*($Q$2)^2) -> 32.378894 | X107: =VLOOKUP(B107,Policy!$B$5:$F$8,5,FALSE) -> 1.2815516 | Y107: =_xlfn.NORM.DIST(X107,0,1,0)-X107*(1-_xlfn.NORM.DIST(X107,0,1,1)) -> 0.047343175 | Z107: =W107*Y107 -> 1.5329197 | AA107: =1-Z107/S107 -> 0.98892308 | AB107: =V107+X107*W107 -> 59.536483 | AD107: =+X107*W107 -> 41.495222 | AE107: =IF(B107="C",(T107/2),(S107/2)) -> 69.194335 | AF107: =S107/(O107/$Y$1) -> 41.732581 | AG107: =2^ROUNDUP((LN(AF107/SQRT(2))/LN(2)),0) -> 32 | AH107: =O107*$T$3/10^5 -> 1.815555 | AI107: =IF(AH107>=Policy!$E$13,Policy!$C$13,IF(Solution!AH107>=Policy!$E$14,Policy!$C$14,IF(Solution!AH107>=Policy!$E$15,Policy!$C$15,IF(Solution!AH107>=Policy!$E$16,Policy!$C$16,IF(Solution!AH107>=Policy!$E$17,Policy!$C$17,IF(Solution!AH107>=Policy!$E$18,Policy!$C$18,IF(AH107>=Policy!$E$19,Policy!$C$19,Policy!$C$20))))))) -> 6
A108: SPD00542 | B108: B | C108: 0 | D108: 0 | E108: 132.59 | F108: 165.08 | G108: 99.06 | H108: 65.91 | I108: 66.11 | J108: 99.01 | K108: 166.43 | L108: 65.83 | M108: 59.247 | N108: 72.413 | O108: =SUM(C108:N108) -> 991.68 | P108: =AVERAGE(C108:N108) -> 82.64 | Q108: =STDEV(C108:N108) -> 53.932607 | R108: =Q108/P108 -> 0.65262109 | S108: =SQRT(2*$T$1*O108*(365/$Y$1)/(($T$3+$T$4)*$T$2)) -> 125.26428 | U108: =VLOOKUP(B108,Policy!$B$5:$J$8,9,FALSE) -> 5.4405348 | V108: =(O108/$Y$1)*U108 -> 14.781561 | W108: =SQRT($Q$1*(Q108/SQRT($Y$2))^2+(O108/$Y$1)^2*($Q$2)^2) -> 22.990029 | X108: =VLOOKUP(B108,Policy!$B$5:$F$8,5,FALSE) -> 1.2815516 | Y108: =_xlfn.NORM.DIST(X108,0,1,0)-X108*(1-_xlfn.NORM.DIST(X108,0,1,1)) -> 0.047343175 | Z108: =W108*Y108 -> 1.088421 | AA108: =1-Z108/S108 -> 0.991311 | AB108: =V108+X108*W108 -> 44.244468 | AD108: =+X108*W108 -> 29.462907 | AE108: =IF(B108="C",(T108/2),(S108/2)) -> 62.632139 | AF108: =S108/(O108/$Y$1) -> 46.105055 | AG108: =2^ROUNDUP((LN(AF108/SQRT(2))/LN(2)),0) -> 64 | AH108: =O108*$T$3/10^5 -> 1.48752 | AI108: =IF(AH108>=Policy!$E$13,Policy!$C$13,IF(Solution!AH108>=Policy!$E$14,Policy!$C$14,IF(Solution!AH108>=Policy!$E$15,Policy!$C$15,IF(Solution!AH108>=Policy!$E$16,Policy!$C$16,IF(Solution!AH108>=Policy!$E$17,Policy!$C$17,IF(Solution!AH108>=Policy!$E$18,Policy!$C$18,IF(AH108>=Policy!$E$19,Policy!$C$19,Policy!$C$20))))))) -> 7
A109: SPD00964 | B109: B | C109: 0 | D109: 0 | E109: 0 | F109: 0 | G109: 0 | H109: 852.2 | I109: 0 | J109: 0 | K109: 0 | L109: 0 | M109: 0 | N109: 0 | O109: =SUM(C109:N109) -> 852.2 | P109: =AVERAGE(C109:N109) -> 71.016667 | Q109: =STDEV(C109:N109) -> 246.00895 | R109: =Q109/P109 -> 3.4641016 | S109: =SQRT(2*$T$1*O109*(365/$Y$1)/(($T$3+$T$4)*$T$2)) -> 116.12139 | U109: =VLOOKUP(B109,Policy!$B$5:$J$8,9,FALSE) -> 5.4405348 | V109: =(O109/$Y$1)*U109 -> 12.702531 | W109: =SQRT($Q$1*(Q109/SQRT($Y$2))^2+(O109/$Y$1)^2*($Q$2)^2) -> 104.07306 | X109: =VLOOKUP(B109,Policy!$B$5:$F$8,5,FALSE) -> 1.2815516 | Y109: =_xlfn.NORM.DIST(X109,0,1,0)-X109*(1-_xlfn.NORM.DIST(X109,0,1,1)) -> 0.047343175 | Z109: =W109*Y109 -> 4.9271491 | AA109: =1-Z109/S109 -> 0.95756898 | AB109: =V109+X109*W109 -> 146.07752 | AD109: =+X109*W109 -> 133.37499 | AE109: =IF(B109="C",(T109/2),(S109/2)) -> 58.060695 | AF109: =S109/(O109/$Y$1) -> 49.735165 | AG109: =2^ROUNDUP((LN(AF109/SQRT(2))/LN(2)),0) -> 64 | AH109: =O109*$T$3/10^5 -> 1.2783 | AI109: =IF(AH109>=Policy!$E$13,Policy!$C$13,IF(Solution!AH109>=Policy!$E$14,Policy!$C$14,IF(Solution!AH109>=Policy!$E$15,Policy!$C$15,IF(Solution!AH109>=Policy!$E$16,Policy!$C$16,IF(Solution!AH109>=Policy!$E$17,Policy!$C$17,IF(Solution!AH109>=Policy!$E$18,Policy!$C$18,IF(AH109>=Policy!$E$19,Policy!$C$19,Policy!$C$20))))))) -> 7
A110: SPD00496 | B110: B | C110: 69.11 | D110: 68.87 | E110: 103.32 | F110: 306.63 | G110: 101.44 | H110: 202.01 | I110: 0 | J110: 0 | K110: 0 | L110: 0 | M110: 0 | N110: 0 | O110: =SUM(C110:N110) -> 851.38 | P110: =AVERAGE(C110:N110) -> 70.948333 | Q110: =STDEV(C110:N110) -> 97.659134 | R110: =Q110/P110 -> 1.3764824 | S110: =SQRT(2*$T$1*O110*(365/$Y$1)/(($T$3+$T$4)*$T$2)) -> 116.06551 | U110: =VLOOKUP(B110,Policy!$B$5:$J$8,9,FALSE) -> 5.4405348 | V110: =(O110/$Y$1)*U110 -> 12.690308 | W110: =SQRT($Q$1*(Q110/SQRT($Y$2))^2+(O110/$Y$1)^2*($Q$2)^2) -> 41.376339 | X110: =VLOOKUP(B110,Policy!$B$5:$F$8,5,FALSE) -> 1.2815516 | Y110: =_xlfn.NORM.DIST(X110,0,1,0)-X110*(1-_xlfn.NORM.DIST(X110,0,1,1)) -> 0.047343175 | Z110: =W110*Y110 -> 1.9588873 | AA110: =1-Z110/S110 -> 0.98312257 | AB110: =V110+X110*W110 -> 65.71622 | AD110: =+X110*W110 -> 53.025912 | AE110: =IF(B110="C",(T110/2),(S110/2)) -> 58.032755 | AF110: =S110/(O110/$Y$1) -> 49.75911 | AG110: =2^ROUNDUP((LN(AF110/SQRT(2))/LN(2)),0) -> 64 | AH110: =O110*$T$3/10^5 -> 1.27707 | AI110: =IF(AH110>=Policy!$E$13,Policy!$C$13,IF(Solution!AH110>=Policy!$E$14,Policy!$C$14,IF(Solution!AH110>=Policy!$E$15,Policy!$C$15,IF(Solution!AH110>=Policy!$E$16,Policy!$C$16,IF(Solution!AH110>=Policy!$E$17,Policy!$C$17,IF(Solution!AH110>=Policy!$E$18,Policy!$C$18,IF(AH110>=Policy!$E$19,Policy!$C$19,Policy!$C$20))))))) -> 7
A111: SPD00445 | B111: B | C111: 0 | D111: 0 | E111: 0 | F111: 0 | G111: 0 | H111: 157.48 | I111: 0 | J111: 0 | K111: 409.23 | L111: 280.93 | M111: 252.837 | N111: 309.023 | O111: =SUM(C111:N111) -> 1409.5 | P111: =AVERAGE(C111:N111) -> 117.45833 | Q111: =STDEV(C111:N111) -> 155.22859 | R111: =Q111/P111 -> 1.321563 | S111: =SQRT(2*$T$1*O111*(365/$Y$1)/(($T$3+$T$4)*$T$2)) -> 149.33926 | U111: =VLOOKUP(B111,Policy!$B$5:$J$8,9,FALSE) -> 5.4405348 | V111: =(O111/$Y$1)*U111 -> 21.009408 | W111: =SQRT($Q$1*(Q111/SQRT($Y$2))^2+(O111/$Y$1)^2*($Q$2)^2) -> 65.777361 | X111: =VLOOKUP(B111,Policy!$B$5:$F$8,5,FALSE) -> 1.2815516 | Y111: =_xlfn.NORM.DIST(X111,0,1,0)-X111*(1-_xlfn.NORM.DIST(X111,0,1,1)) -> 0.047343175 | Z111: =W111*Y111 -> 3.1141092 | AA111: =1-Z111/S111 -> 0.97914742 | AB111: =V111+X111*W111 -> 105.30649 | AD111: =+X111*W111 -> 84.297081 | AE111: =IF(B111="C",(T111/2),(S111/2)) -> 74.669631 | AF111: =S111/(O111/$Y$1) -> 38.672459 | AG111: =2^ROUNDUP((LN(AF111/SQRT(2))/LN(2)),0) -> 32 | AH111: =O111*$T$3/10^5 -> 2.11425 | AI111: =IF(AH111>=Policy!$E$13,Policy!$C$13,IF(Solution!AH111>=Policy!$E$14,Policy!$C$14,IF(Solution!AH111>=Policy!$E$15,Policy!$C$15,IF(Solution!AH111>=Policy!$E$16,Policy!$C$16,IF(Solution!AH111>=Policy!$E$17,Policy!$C$17,IF(Solution!AH111>=Policy!$E$18,Policy!$C$18,IF(AH111>=Policy!$E$19,Policy!$C$19,Policy!$C$20))))))) -> 6
A112: SPD00889 | B112: B | C112: 0 | D112: 0 | E112: 824.83 | F112: 0 | G112: 0 | H112: 0 | I112: 0 | J112: 0 | K112: 0 | L112: 0 | M112: 0 | N112: 0 | O112: =SUM(C112:N112) -> 824.83 | P112: =AVERAGE(C112:N112) -> 68.735833 | Q112: =STDEV(C112:N112) -> 238.10791 | R112: =Q112/P112 -> 3.4641016 | S112: =SQRT(2*$T$1*O112*(365/$Y$1)/(($T$3+$T$4)*$T$2)) -> 114.24144 | U112: =VLOOKUP(B112,Policy!$B$5:$J$8,9,FALSE) -> 5.4405348 | V112: =(O112/$Y$1)*U112 -> 12.294565 | W112: =SQRT($Q$1*(Q112/SQRT($Y$2))^2+(O112/$Y$1)^2*($Q$2)^2) -> 100.73056 | X112: =VLOOKUP(B112,Policy!$B$5:$F$8,5,FALSE) -> 1.2815516 | Y112: =_xlfn.NORM.DIST(X112,0,1,0)-X112*(1-_xlfn.NORM.DIST(X112,0,1,1)) -> 0.047343175 | Z112: =W112*Y112 -> 4.7689045 | AA112: =1-Z112/S112 -> 0.95825592 | AB112: =V112+X112*W112 -> 141.38597 | AD112: =+X112*W112 -> 129.0914 | AE112: =IF(B112="C",(T112/2),(S112/2)) -> 57.120722 | AF112: =S112/(O112/$Y$1) -> 50.553602 | AG112: =2^ROUNDUP((LN(AF112/SQRT(2))/LN(2)),0) -> 64 | AH112: =O112*$T$3/10^5 -> 1.237245 | AI112: =IF(AH112>=Policy!$E$13,Policy!$C$13,IF(Solution!AH112>=Policy!$E$14,Policy!$C$14,IF(Solution!AH112>=Policy!$E$15,Policy!$C$15,IF(Solution!AH112>=Policy!$E$16,Policy!$C$16,IF(Solution!AH112>=Policy!$E$17,Policy!$C$17,IF(Solution!AH112>=Policy!$E$18,Policy!$C$18,IF(AH112>=Policy!$E$19,Policy!$C$19,Policy!$C$20))))))) -> 7
A113: SPD00429 | B113: B | C113: 0 | D113: 0 | E113: 539.73 | F113: 85.3 | G113: 0 | H113: 113.8 | I113: 0 | J113: 28.53 | K113: 28.55 | L113: 28.43 | M113: 25.587 | N113: 31.273 | O113: =SUM(C113:N113) -> 881.2 | P113: =AVERAGE(C113:N113) -> 73.433333 | Q113: =STDEV(C113:N113) -> 151.02546 | R113: =Q113/P113 -> 2.0566335 | S113: =SQRT(2*$T$1*O113*(365/$Y$1)/(($T$3+$T$4)*$T$2)) -> 118.08064 | U113: =VLOOKUP(B113,Policy!$B$5:$J$8,9,FALSE) -> 5.4405348 | V113: =(O113/$Y$1)*U113 -> 13.134793 | W113: =SQRT($Q$1*(Q113/SQRT($Y$2))^2+(O113/$Y$1)^2*($Q$2)^2) -> 63.923757 | X113: =VLOOKUP(B113,Policy!$B$5:$F$8,5,FALSE) -> 1.2815516 | Y113: =_xlfn.NORM.DIST(X113,0,1,0)-X113*(1-_xlfn.NORM.DIST(X113,0,1,1)) -> 0.047343175 | Z113: =W113*Y113 -> 3.0263536 | AA113: =1-Z113/S113 -> 0.97437045 | AB113: =V113+X113*W113 -> 95.056383 | AD113: =+X113*W113 -> 81.92159 | AE113: =IF(B113="C",(T113/2),(S113/2)) -> 59.040321 | AF113: =S113/(O113/$Y$1) -> 48.909934 | AG113: =2^ROUNDUP((LN(AF113/SQRT(2))/LN(2)),0) -> 64 | AH113: =O113*$T$3/10^5 -> 1.3218 | AI113: =IF(AH113>=Policy!$E$13,Policy!$C$13,IF(Solution!AH113>=Policy!$E$14,Policy!$C$14,IF(Solution!AH113>=Policy!$E$15,Policy!$C$15,IF(Solution!AH113>=Policy!$E$16,Policy!$C$16,IF(Solution!AH113>=Policy!$E$17,Policy!$C$17,IF(Solution!AH113>=Policy!$E$18,Policy!$C$18,IF(AH113>=Policy!$E$19,Policy!$C$19,Policy!$C$20))))))) -> 7
A114: SPD00916 | B114: B | C114: 226.97 | D114: 188.42 | E114: 0 | F114: 339.81 | G114: 0 | H114: 37.85 | I114: 0 | J114: 25.15 | K114: 0 | L114: 0 | M114: 0 | N114: 0 | O114: =SUM(C114:N114) -> 818.2 | P114: =AVERAGE(C114:N114) -> 68.183333 | Q114: =STDEV(C114:N114) -> 116.29346 | R114: =Q114/P114 -> 1.7055995 | S114: =SQRT(2*$T$1*O114*(365/$Y$1)/(($T$3+$T$4)*$T$2)) -> 113.78138 | U114: =VLOOKUP(B114,Policy!$B$5:$J$8,9,FALSE) -> 5.4405348 | V114: =(O114/$Y$1)*U114 -> 12.195741 | W114: =SQRT($Q$1*(Q114/SQRT($Y$2))^2+(O114/$Y$1)^2*($Q$2)^2) -> 49.24077 | X114: =VLOOKUP(B114,Policy!$B$5:$F$8,5,FALSE) -> 1.2815516 | Y114: =_xlfn.NORM.DIST(X114,0,1,0)-X114*(1-_xlfn.NORM.DIST(X114,0,1,1)) -> 0.047343175 | Z114: =W114*Y114 -> 2.3312144 | AA114: =1-Z114/S114 -> 0.97951146 | AB114: =V114+X114*W114 -> 75.300327 | AD114: =+X114*W114 -> 63.104586 | AE114: =IF(B114="C",(T114/2),(S114/2)) -> 56.89069 | AF114: =S114/(O114/$Y$1) -> 50.75801 | AG114: =2^ROUNDUP((LN(AF114/SQRT(2))/LN(2)),0) -> 64 | AH114: =O114*$T$3/10^5 -> 1.2273 | AI114: =IF(AH114>=Policy!$E$13,Policy!$C$13,IF(Solution!AH114>=Policy!$E$14,Policy!$C$14,IF(Solution!AH114>=Policy!$E$15,Policy!$C$15,IF(Solution!AH114>=Policy!$E$16,Policy!$C$16,IF(Solution!AH114>=Policy!$E$17,Policy!$C$17,IF(Solution!AH114>=Policy!$E$18,Policy!$C$18,IF(AH114>=Policy!$E$19,Policy!$C$19,Policy!$C$20))))))) -> 7
A115: SPD00263 | B115: B | C115: 0 | D115: 0 | E115: 148.72 | F115: 119.52 | G115: 0 | H115: 239.58 | I115: 0 | J115: 300.39 | K115: 0 | L115: 0 | M115: 0 | N115: 0 | O115: =SUM(C115:N115) -> 808.21 | P115: =AVERAGE(C115:N115) -> 67.350833 | Q115: =STDEV(C115:N115) -> 108.54483 | R115: =Q115/P115 -> 1.6116331 | S115: =SQRT(2*$T$1*O115*(365/$Y$1)/(($T$3+$T$4)*$T$2)) -> 113.08463 | U115: =VLOOKUP(B115,Policy!$B$5:$J$8,9,FALSE) -> 5.4405348 | V115: =(O115/$Y$1)*U115 -> 12.046835 | W115: =SQRT($Q$1*(Q115/SQRT($Y$2))^2+(O115/$Y$1)^2*($Q$2)^2) -> 45.966259 | X115: =VLOOKUP(B115,Policy!$B$5:$F$8,5,FALSE) -> 1.2815516 | Y115: =_xlfn.NORM.DIST(X115,0,1,0)-X115*(1-_xlfn.NORM.DIST(X115,0,1,1)) -> 0.047343175 | Z115: =W115*Y115 -> 2.1761887 | AA115: =1-Z115/S115 -> 0.98075611 | AB115: =V115+X115*W115 -> 70.954966 | AD115: =+X115*W115 -> 58.908132 | AE115: =IF(B115="C",(T115/2),(S115/2)) -> 56.542314 | AF115: =S115/(O115/$Y$1) -> 51.070748 | AG115: =2^ROUNDUP((LN(AF115/SQRT(2))/LN(2)),0) -> 64 | AH115: =O115*$T$3/10^5 -> 1.212315 | AI115: =IF(AH115>=Policy!$E$13,Policy!$C$13,IF(Solution!AH115>=Policy!$E$14,Policy!$C$14,IF(Solution!AH115>=Policy!$E$15,Policy!$C$15,IF(Solution!AH115>=Policy!$E$16,Policy!$C$16,IF(Solution!AH115>=Policy!$E$17,Policy!$C$17,IF(Solution!AH115>=Policy!$E$18,Policy!$C$18,IF(AH115>=Policy!$E$19,Policy!$C$19,Policy!$C$20))))))) -> 7
... A129: SPD00297 | B129: B | C129: 106.39 | D129: 71.34 | E129: 0 | F129: 0 | G129: 0 | H129: 141.6 | I129: 35.38 | J129: 0 | K129: 175.9 | L129: 70.25 | M129: 63.225 | N129: 77.275 | O129: =SUM(C129:N129) -> 741.36 | P129: =AVERAGE(C129:N129) -> 61.78 | Q129: =STDEV(C129:N129) -> 58.584834 | R129: =Q129/P129 -> 0.94828154 | S129: =SQRT(2*$T$1*O129*(365/$Y$1)/(($T$3+$T$4)*$T$2)) -> 108.30688 | U129: =VLOOKUP(B129,Policy!$B$5:$J$8,9,FALSE) -> 5.4405348 | V129: =(O129/$Y$1)*U129 -> 11.050397 | W129: =SQRT($Q$1*(Q129/SQRT($Y$2))^2+(O129/$Y$1)^2*($Q$2)^2) -> 24.870141 | X129: =VLOOKUP(B129,Policy!$B$5:$F$8,5,FALSE) -> 1.2815516 | Y129: =_xlfn.NORM.DIST(X129,0,1,0)-X129*(1-_xlfn.NORM.DIST(X129,0,1,1)) -> 0.047343175 | Z129: =W129*Y129 -> 1.1774314 | AA129: =1-Z129/S129 -> 0.98912875 | AB129: =V129+X129*W129 -> 42.922765 | AD129: =+X129*W129 -> 31.872368 | AE129: =IF(B129="C",(T129/2),(S129/2)) -> 54.153439 | AF129: =S129/(O129/$Y$1) -> 53.323635 | AG129: =2^ROUNDUP((LN(AF129/SQRT(2))/LN(2)),0) -> 64 | AH129: =O129*$T$3/10^5 -> 1.11204 | AI129: =IF(AH129>=Policy!$E$13,Policy!$C$13,IF(Solution!AH129>=Policy!$E$14,Policy!$C$14,IF(Solution!AH129>=Policy!$E$15,Policy!$C$15,IF(Solution!AH129>=Policy!$E$16,Policy!$C$16,IF(Solution!AH129>=Policy!$E$17,Policy!$C$17,IF(Solution!AH129>=Policy!$E$18,Policy!$C$18,IF(AH129>=Policy!$E$19,Policy!$C$19,Policy!$C$20))))))) -> 8
A130: SPD00375 | B130: C | C130: 91.65 | D130: 0 | E130: 122.16 | F130: 122.1 | G130: 0 | H130: 121.84 | I130: 60.97 | J130: 0 | K130: 0 | L130: 60.98 | M130: 54.882 | N130: 67.078 | O130: =SUM(C130:N130) -> 701.66 | P130: =AVERAGE(C130:N130) -> 58.471667 | Q130: =STDEV(C130:N130) -> 49.540018 | R130: =Q130/P130 -> 0.84724827 | T130: =(O130/$Y$1)*U130 -> 68.129331 | U130: =VLOOKUP(B130,Policy!$B$5:$J$8,9,FALSE) -> 35.440535 | V130: =(O130/$Y$1)*U130 -> 68.129331 | W130: =SQRT($Q$1*(Q130/SQRT($Y$2))^2+(O130/$Y$1)^2*($Q$2)^2) -> 21.05032 | X130: =VLOOKUP(B130,Policy!$B$5:$F$8,5,FALSE) -> 0.84162123 | Y130: =_xlfn.NORM.DIST(X130,0,1,0)-X130*(1-_xlfn.NORM.DIST(X130,0,1,1)) -> 0.11163767 | Z130: =W130*Y130 -> 2.3500088 | AA130: =1-Z130/T130 -> 0.96550665 | AC130: =+V130+X130*W130 -> 85.845727 | AD130: =+X130*W130 -> 17.716397 | AE130: =IF(B130="C",(T130/2),(S130/2)) -> 34.064665 | AF130: =T130/(O130/$Y$1) -> 35.440535 | AG130: =2^ROUNDUP((LN(AF130/SQRT(2))/LN(2)),0) -> 32 | AH130: =O130*$T$3/10^5 -> 1.05249 | AI130: =IF(AH130>=Policy!$E$13,Policy!$C$13,IF(Solution!AH130>=Policy!$E$14,Policy!$C$14,IF(Solution!AH130>=Policy!$E$15,Policy!$C$15,IF(Solution!AH130>=Policy!$E$16,Policy!$C$16,IF(Solution!AH130>=Policy!$E$17,Policy!$C$17,IF(Solution!AH130>=Policy!$E$18,Policy!$C$18,IF(AH130>=Policy!$E$19,Policy!$C$19,Policy!$C$20))))))) -> 8
A131: SPD00814 | B131: C | C131: 0 | D131: 0 | E131: 0 | F131: 179.95 | G131: 0 | H131: 0 | I131: 0 | J131: 92.11 | K131: 302.62 | L131: 0 | M131: 0 | N131: 0 | O131: =SUM(C131:N131) -> 574.68 | P131: =AVERAGE(C131:N131) -> 47.89 | Q131: =STDEV(C131:N131) -> 97.665335 | R131: =Q131/P131 -> 2.039368 | T131: =(O131/$Y$1)*U131 -> 55.799908 | U131: =VLOOKUP(B131,Policy!$B$5:$J$8,9,FALSE) -> 35.440535 | V131: =(O131/$Y$1)*U131 -> 55.799908 | W131: =SQRT($Q$1*(Q131/SQRT($Y$2))^2+(O131/$Y$1)^2*($Q$2)^2) -> 41.338858 | X131: =VLOOKUP(B131,Policy!$B$5:$F$8,5,FALSE) -> 0.84162123 | Y131: =_xlfn.NORM.DIST(X131,0,1,0)-X131*(1-_xlfn.NORM.DIST(X131,0,1,1)) -> 0.11163767 | Z131: =W131*Y131 -> 4.6149739 | AA131: =1-Z131/T131 -> 0.91729424 | AC131: =+V131+X131*W131 -> 90.591569 | AD131: =+X131*W131 -> 34.791661 | AE131: =IF(B131="C",(T131/2),(S131/2)) -> 27.899954 | AF131: =T131/(O131/$Y$1) -> 35.440535 | AG131: =2^ROUNDUP((LN(AF131/SQRT(2))/LN(2)),0) -> 32 | AH131: =O131*$T$3/10^5 -> 0.86202 | AI131: =IF(AH131>=Policy!$E$13,Policy!$C$13,IF(Solution!AH131>=Policy!$E$14,Policy!$C$14,IF(Solution!AH131>=Policy!$E$15,Policy!$C$15,IF(Solution!AH131>=Policy!$E$16,Policy!$C$16,IF(Solution!AH131>=Policy!$E$17,Policy!$C$17,IF(Solution!AH131>=Policy!$E$18,Policy!$C$18,IF(AH131>=Policy!$E$19,Policy!$C$19,Policy!$C$20))))))) -> 8
A132: SPD00551 | B132: C | C132: 134.81 | D132: 0 | E132: 270.18 | F132: 0 | G132: 0 | H132: 0 | I132: 0 | J132: 101.49 | K132: 67.61 | L132: 0 | M132: 0 | N132: 0 | O132: =SUM(C132:N132) -> 574.09 | P132: =AVERAGE(C132:N132) -> 47.840833 | Q132: =STDEV(C132:N132) -> 84.518614 | R132: =Q132/P132 -> 1.7666627 | T132: =(O132/$Y$1)*U132 -> 55.742621 | U132: =VLOOKUP(B132,Policy!$B$5:$J$8,9,FALSE) -> 35.440535 | V132: =(O132/$Y$1)*U132 -> 55.742621 | W132: =SQRT($Q$1*(Q132/SQRT($Y$2))^2+(O132/$Y$1)^2*($Q$2)^2) -> 35.7839 | X132: =VLOOKUP(B132,Policy!$B$5:$F$8,5,FALSE) -> 0.84162123 | Y132: =_xlfn.NORM.DIST(X132,0,1,0)-X132*(1-_xlfn.NORM.DIST(X132,0,1,1)) -> 0.11163767 | Z132: =W132*Y132 -> 3.9948314 | AA132: =1-Z132/T132 -> 0.92833435 | AC132: =+V132+X132*W132 -> 85.859111 | AD132: =+X132*W132 -> 30.11649 | AE132: =IF(B132="C",(T132/2),(S132/2)) -> 27.87131 | AF132: =T132/(O132/$Y$1) -> 35.440535 | AG132: =2^ROUNDUP((LN(AF132/SQRT(2))/LN(2)),0) -> 32 | AH132: =O132*$T$3/10^5 -> 0.861135 | AI132: =IF(AH132>=Policy!$E$13,Policy!$C$13,IF(Solution!AH132>=Policy!$E$14,Policy!$C$14,IF(Solution!AH132>=Policy!$E$15,Policy!$C$15,IF(Solution!AH132>=Policy!$E$16,Policy!$C$16,IF(Solution!AH132>=Policy!$E$17,Policy!$C$17,IF(Solution!AH132>=Policy!$E$18,Policy!$C$18,IF(AH132>=Policy!$E$19,Policy!$C$19,Policy!$C$20))))))) -> 8
A133: SPD00040 | B133: C | C133: 0 | D133: 62.27 | E133: 0 | F133: 0 | G133: 93.29 | H133: 0 | I133: 0 | J133: 0 | K133: 0 | L133: 405.5 | M133: 364.95 | N133: 446.05 | O133: =SUM(C133:N133) -> 1372.06 | P133: =AVERAGE(C133:N133) -> 114.33833 | Q133: =STDEV(C133:N133) -> 178.95679 | R133: =Q133/P133 -> 1.5651513 | T133: =(O133/$Y$1)*U133 -> 133.2234 | U133: =VLOOKUP(B133,Policy!$B$5:$J$8,9,FALSE) -> 35.440535 | V133: =(O133/$Y$1)*U133 -> 133.2234 | W133: =SQRT($Q$1*(Q133/SQRT($Y$2))^2+(O133/$Y$1)^2*($Q$2)^2) -> 75.790056 | X133: =VLOOKUP(B133,Policy!$B$5:$F$8,5,FALSE) -> 0.84162123 | Y133: =_xlfn.NORM.DIST(X133,0,1,0)-X133*(1-_xlfn.NORM.DIST(X133,0,1,1)) -> 0.11163767 | Z133: =W133*Y133 -> 8.4610255 | AA133: =1-Z133/T133 -> 0.93648994 | AC133: =+V133+X133*W133 -> 197.00992 | AD133: =+X133*W133 -> 63.78652 | AE133: =IF(B133="C",(T133/2),(S133/2)) -> 66.611699 | AF133: =T133/(O133/$Y$1) -> 35.440535 | AG133: =2^ROUNDUP((LN(AF133/SQRT(2))/LN(2)),0) -> 32 | AH133: =O133*$T$3/10^5 -> 2.05809 | AI133: =IF(AH133>=Policy!$E$13,Policy!$C$13,IF(Solution!AH133>=Policy!$E$14,Policy!$C$14,IF(Solution!AH133>=Policy!$E$15,Policy!$C$15,IF(Solution!AH133>=Policy!$E$16,Policy!$C$16,IF(Solution!AH133>=Policy!$E$17,Policy!$C$17,IF(Solution!AH133>=Policy!$E$18,Policy!$C$18,IF(AH133>=Policy!$E$19,Policy!$C$19,Policy!$C$20))))))) -> 6
A134: SPD00464 | B134: C | C134: 0 | D134: 0 | E134: 114.32 | F134: 152.54 | G134: 0 | H134: 190.28 | I134: 76.91 | J134: 0 | K134: 0 | L134: 0 | M134: 0 | N134: 0 | O134: =SUM(C134:N134) -> 534.05 | P134: =AVERAGE(C134:N134) -> 44.504167 | Q134: =STDEV(C134:N134) -> 70.512211 | R134: =Q134/P134 -> 1.5843957 | T134: =(O134/$Y$1)*U134 -> 51.854843 | U134: =VLOOKUP(B134,Policy!$B$5:$J$8,9,FALSE) -> 35.440535 | V134: =(O134/$Y$1)*U134 -> 51.854843 | W134: =SQRT($Q$1*(Q134/SQRT($Y$2))^2+(O134/$Y$1)^2*($Q$2)^2) -> 29.861658 | X134: =VLOOKUP(B134,Policy!$B$5:$F$8,5,FALSE) -> 0.84162123 | Y134: =_xlfn.NORM.DIST(X134,0,1,0)-X134*(1-_xlfn.NORM.DIST(X134,0,1,1)) -> 0.11163767 | Z134: =W134*Y134 -> 3.333686 | AA134: =1-Z134/T134 -> 0.93571119 | AC134: =+V134+X134*W134 -> 76.987048 | AD134: =+X134*W134 -> 25.132206 | AE134: =IF(B134="C",(T134/2),(S134/2)) -> 25.927421 | AF134: =T134/(O134/$Y$1) -> 35.440535 | AG134: =2^ROUNDUP((LN(AF134/SQRT(2))/LN(2)),0) -> 32 | AH134: =O134*$T$3/10^5 -> 0.801075 | AI134: =IF(AH134>=Policy!$E$13,Policy!$C$13,IF(Solution!AH134>=Policy!$E$14,Policy!$C$14,IF(Solution!AH134>=Policy!$E$15,Policy!$C$15,IF(Solution!AH134>=Policy!$E$16,Policy!$C$16,IF(Solution!AH134>=Policy!$E$17,Policy!$C$17,IF(Solution!AH134>=Policy!$E$18,Policy!$C$18,IF(AH134>=Policy!$E$19,Policy!$C$19,Policy!$C$20))))))) -> 8
A135: SPD00411 | B135: C | C135: 106.55 | D135: 0 | E135: 79.73 | F135: 132.86 | G135: 0 | H135: 0 | I135: 26.46 | J135: 133.86 | K135: 0 | L135: 53.99 | M135: 48.591 | N135: 59.389 | O135: =SUM(C135:N135) -> 641.43 | P135: =AVERAGE(C135:N135) -> 53.4525 | Q135: =STDEV(C135:N135) -> 50.89848 | R135: =Q135/P135 -> 0.95221888 | T135: =(O135/$Y$1)*U135 -> 62.281157 | U135: =VLOOKUP(B135,Policy!$B$5:$J$8,9,FALSE) -> 35.440535 | V135: =(O135/$Y$1)*U135 -> 62.281157 | W135: =SQRT($Q$1*(Q135/SQRT($Y$2))^2+(O135/$Y$1)^2*($Q$2)^2) -> 21.606502 | X135: =VLOOKUP(B135,Policy!$B$5:$F$8,5,FALSE) -> 0.84162123 | Y135: =_xlfn.NORM.DIST(X135,0,1,0)-X135*(1-_xlfn.NORM.DIST(X135,0,1,1)) -> 0.11163767 | Z135: =W135*Y135 -> 2.4120996 | AA135: =1-Z135/T135 -> 0.9612708 | AC135: =+V135+X135*W135 -> 80.465648 | AD135: =+X135*W135 -> 18.184491 | AE135: =IF(B135="C",(T135/2),(S135/2)) -> 31.140578 | AF135: =T135/(O135/$Y$1) -> 35.440535 | AG135: =2^ROUNDUP((LN(AF135/SQRT(2))/LN(2)),0) -> 32 | AH135: =O135*$T$3/10^5 -> 0.962145 | AI135: =IF(AH135>=Policy!$E$13,Policy!$C$13,IF(Solution!AH135>=Policy!$E$14,Policy!$C$14,IF(Solution!AH135>=Policy!$E$15,Policy!$C$15,IF(Solution!AH135>=Policy!$E$16,Policy!$C$16,IF(Solution!AH135>=Policy!$E$17,Policy!$C$17,IF(Solution!AH135>=Policy!$E$18,Policy!$C$18,IF(AH135>=Policy!$E$19,Policy!$C$19,Policy!$C$20))))))) -> 8
A136: SPD00716 | B136: C | C136: 0 | D136: 0 | E136: 0 | F136: 0 | G136: 0 | H136: 421.2 | I136: 0 | J136: 0 | K136: 105.49 | L136: 0 | M136: 0 | N136: 0 | O136: =SUM(C136:N136) -> 526.69 | P136: =AVERAGE(C136:N136) -> 43.890833 | Q136: =STDEV(C136:N136) -> 122.63053 | R136: =Q136/P136 -> 2.7939896 | T136: =(O136/$Y$1)*U136 -> 51.140206 | U136: =VLOOKUP(B136,Policy!$B$5:$J$8,9,FALSE) -> 35.440535 | V136: =(O136/$Y$1)*U136 -> 51.140206 | W136: =SQRT($Q$1*(Q136/SQRT($Y$2))^2+(O136/$Y$1)^2*($Q$2)^2) -> 51.886187 | X136: =VLOOKUP(B136,Policy!$B$5:$F$8,5,FALSE) -> 0.84162123 | Y136: =_xlfn.NORM.DIST(X136,0,1,0)-X136*(1-_xlfn.NORM.DIST(X136,0,1,1)) -> 0.11163767 | Z136: =W136*Y136 -> 5.7924532 | AA136: =1-Z136/T136 -> 0.88673387 | AC136: =+V136+X136*W136 -> 94.808723 | AD136: =+X136*W136 -> 43.668517 | AE136: =IF(B136="C",(T136/2),(S136/2)) -> 25.570103 | AF136: =T136/(O136/$Y$1) -> 35.440535 | AG136: =2^ROUNDUP((LN(AF136/SQRT(2))/LN(2)),0) -> 32 | AH136: =O136*$T$3/10^5 -> 0.790035 | AI136: =IF(AH136>=Policy!$E$13,Policy!$C$13,IF(Solution!AH136>=Policy!$E$14,Policy!$C$14,IF(Solution!AH136>=Policy!$E$15,Policy!$C$15,IF(Solution!AH136>=Policy!$E$16,Policy!$C$16,IF(Solution!AH136>=Policy!$E$17,Policy!$C$17,IF(Solution!AH136>=Policy!$E$18,Policy!$C$18,IF(AH136>=Policy!$E$19,Policy!$C$19,Policy!$C$20))))))) -> 8
...
